# 2月17日楚天云热迁移失败问题分析

## 问题现象

2017年2月17日，r2202088compute节点上的虚拟机：777fe18a-e88b-4bdd-b84e-4336d9f073bb热迁移到r2202086compute节点过程中，长时间处于migrating状态。

![1487641180(1)](.\image\1487641180(1).jpg)

## 问题分析

查看目的节点r2202086compute的nova-compute.log日志，发现在迁移时间点出现如下错误：

```shell
2017-02-17 16:14:52.790 47766 ERROR nova.network.neutronv2.api [req-31aa48e1-7aca-4b61-ad73-a610df0763b1 48d8cd602577412c978f0184544e9e1c d04021d5a4144b4c9f579fdc1d1c2a9a - - -] Unable to update host of port 4ec88534-df59-4bea-b6bb-43ac07fc1d2d
2017-02-17 16:14:52.790 47766 TRACE nova.network.neutronv2.api Traceback (most recent call last):
2017-02-17 16:14:52.790 47766 TRACE nova.network.neutronv2.api   File "/usr/local/lib/python2.7/dist-packages/nova/network/neutronv2/api.py", line 1697, in _update_port_binding_for_instance
2017-02-17 16:14:52.790 47766 TRACE nova.network.neutronv2.api     {'port': {'binding:host_id': host}})
2017-02-17 16:14:52.790 47766 TRACE nova.network.neutronv2.api   File "/usr/local/lib/python2.7/dist-packages/neutronclient/v2_0/client.py", line 102, in with_params
2017-02-17 16:14:52.790 47766 TRACE nova.network.neutronv2.api     ret = self.function(instance, *args, **kwargs)
2017-02-17 16:14:52.790 47766 TRACE nova.network.neutronv2.api   File "/usr/local/lib/python2.7/dist-packages/neutronclient/v2_0/client.py", line 549, in update_port
2017-02-17 16:14:52.790 47766 TRACE nova.network.neutronv2.api     return self.put(self.port_path % (port), body=body)
2017-02-17 16:14:52.790 47766 TRACE nova.network.neutronv2.api   File "/usr/local/lib/python2.7/dist-packages/neutronclient/v2_0/client.py", line 302, in put
2017-02-17 16:14:52.790 47766 TRACE nova.network.neutronv2.api     headers=headers, params=params)
2017-02-17 16:14:52.790 47766 TRACE nova.network.neutronv2.api   File "/usr/local/lib/python2.7/dist-packages/neutronclient/v2_0/client.py", line 270, in retry_request
2017-02-17 16:14:52.790 47766 TRACE nova.network.neutronv2.api     headers=headers, params=params)
2017-02-17 16:14:52.790 47766 TRACE nova.network.neutronv2.api   File "/usr/local/lib/python2.7/dist-packages/neutronclient/v2_0/client.py", line 200, in do_request
2017-02-17 16:14:52.790 47766 TRACE nova.network.neutronv2.api     content_type=self.content_type())
2017-02-17 16:14:52.790 47766 TRACE nova.network.neutronv2.api   File "/usr/local/lib/python2.7/dist-packages/neutronclient/client.py", line 306, in do_request
2017-02-17 16:14:52.790 47766 TRACE nova.network.neutronv2.api     return self.request(url, method, **kwargs)
2017-02-17 16:14:52.790 47766 TRACE nova.network.neutronv2.api   File "/usr/local/lib/python2.7/dist-packages/neutronclient/client.py", line 294, in request
2017-02-17 16:14:52.790 47766 TRACE nova.network.neutronv2.api     resp = super(SessionClient, self).request(*args, **kwargs)
2017-02-17 16:14:52.790 47766 TRACE nova.network.neutronv2.api   File "/usr/local/lib/python2.7/dist-packages/keystoneclient/adapter.py", line 95, in request
2017-02-17 16:14:52.790 47766 TRACE nova.network.neutronv2.api     return self.session.request(url, method, **kwargs)
2017-02-17 16:14:52.790 47766 TRACE nova.network.neutronv2.api   File "/usr/local/lib/python2.7/dist-packages/keystoneclient/utils.py", line 318, in inner
2017-02-17 16:14:52.790 47766 TRACE nova.network.neutronv2.api     return func(*args, **kwargs)
2017-02-17 16:14:52.790 47766 TRACE nova.network.neutronv2.api   File "/usr/local/lib/python2.7/dist-packages/keystoneclient/session.py", line 382, in request
2017-02-17 16:14:52.790 47766 TRACE nova.network.neutronv2.api     resp = send(**kwargs)
2017-02-17 16:14:52.790 47766 TRACE nova.network.neutronv2.api   File "/usr/local/lib/python2.7/dist-packages/keystoneclient/session.py", line 426, in _send_request
2017-02-17 16:14:52.790 47766 TRACE nova.network.neutronv2.api     raise exceptions.ConnectionRefused(msg)
2017-02-17 16:14:52.790 47766 TRACE nova.network.neutronv2.api ConnectionRefused: Unable to establish connection to http://192.168.202.10:9696/v2.0/ports/4ec88534-df59-4bea-b6bb-43ac07fc1d2d.json

```

日志显示与neutron的endpoint建立连接失败，导致更新端口信息失败。涉及的端口为`4ec88534-df59-4bea-b6bb-43ac07fc1d2d`，对应虚拟机的`192.168.4.40`网卡。

可以确定，是在调用neutron api，执行更新端口操作时出错。

查看neutron-server.log，发现在迁移时间点出现如下错误日志:

```shell
2017-02-17 16:15:01.097 63737 ERROR neutron.restproxy.service.service [req-f3c5407a-b11c-4e6c-ac44-426dc00e10c6 ] request error, operate: GET, url: http://192.168.202.10:8774/v2/d04021d5a4144b4c9f579fdc1d1c2a9a/servers/detail?all_tenants=1&tenant_id=f68888c592b843f4bac96468a7751f36
2017-02-17 16:15:01.097 63737 ERROR neutron.restproxy.service.service [req-f3c5407a-b11c-4e6c-ac44-426dc00e10c6 ] get server by id error, url: http://192.168.202.10:8774/v2/d04021d5a4144b4c9f579fdc1d1c2a9a/servers/detail?all_tenants=1&tenant_id=f68888c592b843f4bac96468a7751f36
2017-02-17 16:15:01.097 63737 ERROR neutron.plugins.ml2.drivers.huawei.mech_huawei [req-f3c5407a-b11c-4e6c-ac44-426dc00e10c6 ] [mech_huawei_driver]get vm name by device id error
2017-02-17 16:15:01.098 63737 WARNING neutron.plugins.ml2.drivers.huawei.mech_huawei [req-f3c5407a-b11c-4e6c-ac44-426dc00e10c6 ] [mech_huawei_driver]can't get vm name
```

日志显示neutron-server在调用nova-api执行`nova list --tenant f68888c592b843f4bac96468a7751f36`时出错。

查看nova-api.log，发现在迁移时间点出现如下错误日志:

```shell
2017-02-17 16:15:01.222 34624 ERROR nova.api.openstack [req-276c5fc9-d70d-4707-8323-15e1e2b67514 48d8cd602577412c978f0184544e9e1c d04021d5a4144b4c9f579fdc1d1c2a9a - - -] Caught error: Unable to establish connection to http://192.168.202.10:9696/v2.0/ports.json?device_id=d26301f8-0c16-401a-a521-43ec51802f63&device_id=777fe18a-e88b-4bdd-b84e-4336d9f073bb&device_id=...
2017-02-17 16:15:01.222 34624 TRACE nova.api.openstack Traceback (most recent call last):
2017-02-17 16:15:01.222 34624 TRACE nova.api.openstack   File "/usr/local/lib/python2.7/dist-packages/nova/api/openstack/__init__.py", line 125, in __call__
2017-02-17 16:15:01.222 34624 TRACE nova.api.openstack     return req.get_response(self.application)
2017-02-17 16:15:01.222 34624 TRACE nova.api.openstack   File "/usr/local/lib/python2.7/dist-packages/webob/request.py", line 1317, in send
2017-02-17 16:15:01.222 34624 TRACE nova.api.openstack     application, catch_exc_info=False)
2017-02-17 16:15:01.222 34624 TRACE nova.api.openstack   File "/usr/local/lib/python2.7/dist-packages/webob/request.py", line 1281, in call_application
2017-02-17 16:15:01.222 34624 TRACE nova.api.openstack     app_iter = application(self.environ, start_response)
2017-02-17 16:15:01.222 34624 TRACE nova.api.openstack   File "/usr/local/lib/python2.7/dist-packages/webob/dec.py", line 144, in __call__
2017-02-17 16:15:01.222 34624 TRACE nova.api.openstack     return resp(environ, start_response)
2017-02-17 16:15:01.222 34624 TRACE nova.api.openstack   File "/usr/local/lib/python2.7/dist-packages/keystonemiddleware/auth_token/__init__.py", line 634, in __call__
2017-02-17 16:15:01.222 34624 TRACE nova.api.openstack     return self._call_app(env, start_response)
2017-02-17 16:15:01.222 34624 TRACE nova.api.openstack   File "/usr/local/lib/python2.7/dist-packages/keystonemiddleware/auth_token/__init__.py", line 554, in _call_app
2017-02-17 16:15:01.222 34624 TRACE nova.api.openstack     return self._app(env, _fake_start_response)
2017-02-17 16:15:01.222 34624 TRACE nova.api.openstack   File "/usr/local/lib/python2.7/dist-packages/webob/dec.py", line 144, in __call__
2017-02-17 16:15:01.222 34624 TRACE nova.api.openstack     return resp(environ, start_response)
2017-02-17 16:15:01.222 34624 TRACE nova.api.openstack   File "/usr/local/lib/python2.7/dist-packages/webob/dec.py", line 144, in __call__
2017-02-17 16:15:01.222 34624 TRACE nova.api.openstack     return resp(environ, start_response)
2017-02-17 16:15:01.222 34624 TRACE nova.api.openstack   File "/usr/local/lib/python2.7/dist-packages/routes/middleware.py", line 136, in __call__
2017-02-17 16:15:01.222 34624 TRACE nova.api.openstack     response = self.app(environ, start_response)
2017-02-17 16:15:01.222 34624 TRACE nova.api.openstack   File "/usr/local/lib/python2.7/dist-packages/webob/dec.py", line 144, in __call__
2017-02-17 16:15:01.222 34624 TRACE nova.api.openstack     return resp(environ, start_response)
2017-02-17 16:15:01.222 34624 TRACE nova.api.openstack   File "/usr/local/lib/python2.7/dist-packages/webob/dec.py", line 130, in __call__
2017-02-17 16:15:01.222 34624 TRACE nova.api.openstack     resp = self.call_func(req, *args, **self.kwargs)
2017-02-17 16:15:01.222 34624 TRACE nova.api.openstack   File "/usr/local/lib/python2.7/dist-packages/webob/dec.py", line 195, in call_func
2017-02-17 16:15:01.222 34624 TRACE nova.api.openstack     return self.func(req, *args, **kwargs)
2017-02-17 16:15:01.222 34624 TRACE nova.api.openstack   File "/usr/local/lib/python2.7/dist-packages/nova/api/openstack/wsgi.py", line 756, in __call__
2017-02-17 16:15:01.222 34624 TRACE nova.api.openstack     content_type, body, accept)
2017-02-17 16:15:01.222 34624 TRACE nova.api.openstack   File "/usr/local/lib/python2.7/dist-packages/nova/api/openstack/wsgi.py", line 847, in _process_stack
2017-02-17 16:15:01.222 34624 TRACE nova.api.openstack     request, action_args)
2017-02-17 16:15:01.222 34624 TRACE nova.api.openstack   File "/usr/local/lib/python2.7/dist-packages/nova/api/openstack/wsgi.py", line 710, in post_process_extensions
2017-02-17 16:15:01.222 34624 TRACE nova.api.openstack     **action_args)
2017-02-17 16:15:01.222 34624 TRACE nova.api.openstack   File "/usr/local/lib/python2.7/dist-packages/nova/api/openstack/compute/contrib/security_groups.py", line 471, in detail
2017-02-17 16:15:01.222 34624 TRACE nova.api.openstack     self._extend_servers(req, list(resp_obj.obj['servers']))
2017-02-17 16:15:01.222 34624 TRACE nova.api.openstack   File "/usr/local/lib/python2.7/dist-packages/nova/api/openstack/compute/contrib/security_groups.py", line 422, in _extend_servers
2017-02-17 16:15:01.222 34624 TRACE nova.api.openstack     servers))
2017-02-17 16:15:01.222 34624 TRACE nova.api.openstack   File "/usr/local/lib/python2.7/dist-packages/nova/network/security_group/neutron_driver.py", line 353, in get_instances_security_groups_bindings
2017-02-17 16:15:01.222 34624 TRACE nova.api.openstack     ports = self._get_ports_from_server_list(servers, neutron)
2017-02-17 16:15:01.222 34624 TRACE nova.api.openstack   File "/usr/local/lib/python2.7/dist-packages/nova/network/security_group/neutron_driver.py", line 312, in _get_ports_from_server_list
2017-02-17 16:15:01.222 34624 TRACE nova.api.openstack     ports.extend(neutron.list_ports(**search_opts).get('ports'))
2017-02-17 16:15:01.222 34624 TRACE nova.api.openstack   File "/usr/local/lib/python2.7/dist-packages/neutronclient/v2_0/client.py", line 102, in with_params
2017-02-17 16:15:01.222 34624 TRACE nova.api.openstack     ret = self.function(instance, *args, **kwargs)
2017-02-17 16:15:01.222 34624 TRACE nova.api.openstack   File "/usr/local/lib/python2.7/dist-packages/neutronclient/v2_0/client.py", line 534, in list_ports
2017-02-17 16:15:01.222 34624 TRACE nova.api.openstack     **_params)
2017-02-17 16:15:01.222 34624 TRACE nova.api.openstack   File "/usr/local/lib/python2.7/dist-packages/neutronclient/v2_0/client.py", line 307, in list
2017-02-17 16:15:01.222 34624 TRACE nova.api.openstack     for r in self._pagination(collection, path, **params):
2017-02-17 16:15:01.222 34624 TRACE nova.api.openstack   File "/usr/local/lib/python2.7/dist-packages/neutronclient/v2_0/client.py", line 320, in _pagination
2017-02-17 16:15:01.222 34624 TRACE nova.api.openstack     res = self.get(path, params=params)
2017-02-17 16:15:01.222 34624 TRACE nova.api.openstack   File "/usr/local/lib/python2.7/dist-packages/neutronclient/v2_0/client.py", line 293, in get
2017-02-17 16:15:01.222 34624 TRACE nova.api.openstack     headers=headers, params=params)
2017-02-17 16:15:01.222 34624 TRACE nova.api.openstack   File "/usr/local/lib/python2.7/dist-packages/neutronclient/v2_0/client.py", line 270, in retry_request
2017-02-17 16:15:01.222 34624 TRACE nova.api.openstack     headers=headers, params=params)
2017-02-17 16:15:01.222 34624 TRACE nova.api.openstack   File "/usr/local/lib/python2.7/dist-packages/neutronclient/v2_0/client.py", line 200, in do_request
2017-02-17 16:15:01.222 34624 TRACE nova.api.openstack     content_type=self.content_type())
2017-02-17 16:15:01.222 34624 TRACE nova.api.openstack   File "/usr/local/lib/python2.7/dist-packages/neutronclient/client.py", line 306, in do_request
2017-02-17 16:15:01.222 34624 TRACE nova.api.openstack     return self.request(url, method, **kwargs)
2017-02-17 16:15:01.222 34624 TRACE nova.api.openstack   File "/usr/local/lib/python2.7/dist-packages/neutronclient/client.py", line 294, in request
2017-02-17 16:15:01.222 34624 TRACE nova.api.openstack     resp = super(SessionClient, self).request(*args, **kwargs)
2017-02-17 16:15:01.222 34624 TRACE nova.api.openstack   File "/usr/local/lib/python2.7/dist-packages/keystoneclient/adapter.py", line 95, in request
2017-02-17 16:15:01.222 34624 TRACE nova.api.openstack     return self.session.request(url, method, **kwargs)
2017-02-17 16:15:01.222 34624 TRACE nova.api.openstack   File "/usr/local/lib/python2.7/dist-packages/keystoneclient/utils.py", line 318, in inner
2017-02-17 16:15:01.222 34624 TRACE nova.api.openstack     return func(*args, **kwargs)
2017-02-17 16:15:01.222 34624 TRACE nova.api.openstack   File "/usr/local/lib/python2.7/dist-packages/keystoneclient/session.py", line 382, in request
2017-02-17 16:15:01.222 34624 TRACE nova.api.openstack     resp = send(**kwargs)
2017-02-17 16:15:01.222 34624 TRACE nova.api.openstack   File "/usr/local/lib/python2.7/dist-packages/keystoneclient/session.py", line 426, in _send_request
2017-02-17 16:15:01.222 34624 TRACE nova.api.openstack     raise exceptions.ConnectionRefused(msg)
```

以及如下日志：

```shell
2017-02-17 16:15:01.239 34624 INFO nova.api.openstack [req-276c5fc9-d70d-4707-8323-15e1e2b67514 48d8cd602577412c978f0184544e9e1c d04021d5a4144b4c9f579fdc1d1c2a9a - - -] http://192.168.202.10:8774/v2/d04021d5a4144b4c9f579fdc1d1c2a9a/servers/detail?all_tenants=1&tenant_id=f68888c592b843f4bac96468a7751f36 returned with HTTP 500
2017-02-17 16:15:01.241 34624 DEBUG nova.api.openstack.wsgi [req-276c5fc9-d70d-4707-8323-15e1e2b67514 48d8cd602577412c978f0184544e9e1c d04021d5a4144b4c9f579fdc1d1c2a9a - - -] Returning 500 to user: The server has either erred or is incapable of performing the requested operation. __call__ /usr/local/lib/python2.7/dist-packages/nova/api/openstack/wsgi.py:1166
2017-02-17 16:15:01.242 34624 INFO nova.osapi_compute.wsgi.server [req-276c5fc9-d70d-4707-8323-15e1e2b67514 48d8cd602577412c978f0184544e9e1c d04021d5a4144b4c9f579fdc1d1c2a9a - - -] Traceback (most recent call last):
  File "/usr/local/lib/python2.7/dist-packages/eventlet/wsgi.py", line 483, in handle_one_response
    write(b''.join(towrite))
  File "/usr/local/lib/python2.7/dist-packages/eventlet/wsgi.py", line 426, in write
    _writelines(towrite)
  File "/usr/lib/python2.7/socket.py", line 334, in writelines
    self.flush()
  File "/usr/lib/python2.7/socket.py", line 303, in flush
    self._sock.sendall(view[write_offset:write_offset+buffer_size])
  File "/usr/local/lib/python2.7/dist-packages/eventlet/greenio/base.py", line 376, in sendall
    tail = self.send(data, flags)
  File "/usr/local/lib/python2.7/dist-packages/eventlet/greenio/base.py", line 359, in send
    total_sent += fd.send(data[total_sent:], flags)
error: [Errno 104] Connection reset by peer
2017-02-17 16:15:01.243 34624 INFO nova.osapi_compute.wsgi.server [req-276c5fc9-d70d-4707-8323-15e1e2b67514 48d8cd602577412c978f0184544e9e1c d04021d5a4144b4c9f579fdc1d1c2a9a - - -] 192.168.202.3 "GET /v2/d04021d5a4144b4c9f579fdc1d1c2a9a/servers/detail?all_tenants=1&tenant_id=f68888c592b843f4bac96468a7751f36 HTTP/1.1" status: 500 len: 0 time: 120.1450701
```

上面的2个日志表示，在`nova list --tenant f68888c592b843f4bac96468a7751f36`执行过程中调用了neutron api执行`neutron port-list`，而`neutron port-list`执行失败了，导致nova list执行失败。

查看haproxy日志，发现如下信息：

```
Feb 17 16:14:52 r2202003haproxy haproxy[34355]: 192.168.202.86:59785 [17/Feb/2017:16:12:52.785] neutron-api neutron-api/nova1 3/0/0/-1/120003 -1 0 - - cD-- 1561/69/1/1/0 0/0 "PUT /v2.0/ports/4ec88534-df59-4bea-b6bb-43ac07fc1d2d.json HTTP/1.1"
```

```
Feb 17 16:15:01 r2202003haproxy haproxy[34355]: 192.168.202.1:48782 [17/Feb/2017:16:13:01.096] nova-api nova-api/nova2 0/0/0/-1/120000 504 194 - - sH-- 1562/3/1/0/0 0/0 "GET /v2/d04021d5a4144b4c9f579fdc1d1c2a9a/servers/detail?all_tenants=1&tenant_id=f68888c592b843f4bac96468a7751f36 HTTP/1.1"
```

综合分析所有日志可以整理出事件顺序：

1. 在16:12:52，目的计算节点通过haproxy发送update-port的请求到neutron-server
2. 在16:13:01，neutron-server通过haproxy发送nova list的请求到nova-api
3. 在16:13:01，nova-api通过haproxy发送port-list的请求给neutron-server
4. 在16:14:52，haproxy的update-port的请求超时，导致目的计算节点报错
5. 在16:15:01，haproxy的nova list的请求超时，导致neutron-server报错
6. 在16:15:01，haproxy的port-list的请求超时，导致nova-api报错

但是在haproxy的日志中，没有发现第3步和第6步相关信息，而且neutron-server中也没有执行port-list的相关日志，所以 ，怀疑该请求没有成功发送到haproxy，使nova list操作超时。

在网络上搜索相关错误，发现tcp连接都有一个超时时间，超过超时时间后，会中断该连接。若恰好在中断连接的时候发出请求，就会出现信息丢失，导致异常发生。

https://bugs.launchpad.net/keystone/+bug/1535640

https://bugs.launchpad.net/nova/+bug/1630664

https://review.openstack.org/#/c/433738/

## 问题复现

在实验环境中，通过tcpkill工具，手动中断controller节点与9696端口的连接，来模拟nova-api与haproxy连接中断。

然后执行`nova list --all`命令，可以得到如下结果：

> root@jycompute42:~# nova list --all
> ERROR (ClientException): The server has either erred or is incapable of performing the requested operation. (HTTP 500) (Request-ID: req-6efbb03e-f7ae-4b12-a36d-15aa131b39a6)

查看nova-api.log，可以发现如下日志信息：

```shell
2017-02-21 08:10:00.912 21943 ERROR nova.api.openstack [req-6efbb03e-f7ae-4b12-a36d-15aa131b39a6 48d8cd602577412c978f0184544e9e1c d04021d5a4144b4c9f579fdc1d1c2a9a - - -] Caught error: Unable to establish connection to http://192.168.1.9:9696/v2.0/ports.json?device_id=41ef348e-2a97-4f6b-a0f1-7788f59c8d64&device_id=e96bba46-1088-4912-90eb-d0fb83cd49d5&device_id=339adb4c-690b-4aa0-864b-073fa1ce4614&device_id=6100c6c3-39ff-4961-8e82-9f7c4c1d3f13&device_id=26713d9f-587f-4cd5-899c-c3aa4b047541&device_id=20df1eaa-ff8b-4060-8bf8-a74726b41f6f&device_id=ae1cbd08-a3cc-4550-a3d3-04ac8b766bd3&device_id=713ec4a3-8d18-418b-aa16-8394698d1ab7&device_id=3abd8c47-8e7d-4d24-bb51-6bcd49ce8511&device_id=e6a6bc57-9e56-46fa-bf00-e5ccec7cc03b&device_id=99644591-523b-4fff-8d72-e1277324cdf2&device_id=be231aa1-3bdd-4e51-a3b5-0828d079faf0&device_id=d659df81-e37b-4b9c-8649-ac835c64da22&device_id=89cf2614-7b31-46a1-b416-bc8f765e6f78
```

实验结果与生产环境中的现象一致。

## 问题原因

热迁移后期，计算节点调用neutron-server执行update-port，neutron-server会去调用nova-api执行nova list，nova list执行过程中又会调用neutron-server执行port-list，在这个过程中nova-api与haproxy的tcp连接中断，这时候nova-api发送给haproxy的请求就会丢失，导致整个热迁移过程失败。

## 解决方案

由于问题是由连接中断引起的，可以在连接中断后开启重试。

在keystoneclient/session.py的request方法中，默认重试次数是0，可以修改代码，当重试次数为0时，设为5。

实验时发现，如果连接被中断，会进行重试。

![1487727157](F:\private\blog\_posts\image\1487727157.jpg)



